Workbook

Sheet 模板1
A1: 团队 | B1: ="完美一单积分完成通报（截至"&MONTH(TODAY()-1)&"月"&DAY(TODAY()-1)&"日）" -> 完美一单积分完成通报（截至8月5日）
B2: 高套 | J2: 完美一单积分 | Q2: 全光组网
B3: 客户经理 | C3: 政企高套目标 | D3: 政企高套发展 | E3: 政企高套完成率 | F3: 时间进度完成率 | G3: 揽装高套（红黄牌考核） | H3: 黄牌预警（低于3户） | I3: 客户经理牌级 | J3: 积分任务值 | K3: 增量积分 | L3: 净增积分 | M3: 积分完成率 | N3: 时间进度完成率 | O3: 排名 | P3: 积分激励预测(元) | Q3: 发展目标 | R3: 主从网关数 | S3: 完成率
A4: 党政军 团队 | B4: 麦海芬 | C4: 14 | D4: =_xlfn.XLOOKUP(B4,高套!A:A,高套!B:B,0) -> 1.5 | E4: =D4/C4 -> 0.10714286 | F4: =D4/(C4/Z4*W$4) -> 0.66428571 | G4: =_xlfn.XLOOKUP(B4,红黄牌高套!A:A,红黄牌高套!B:B,0) -> 1.5 | H4: =IF(G4>=3,"否","是") -> 是 | I4: =IF(G4>=15,"金牌",IF(G4>=12,"银牌","")) | J4: 2500 | K4: =VLOOKUP(B:B,完美一单!A:C,3,0) -> 129 | L4: =_xlfn.XLOOKUP(B4,净增积分!A:A,净增积分!B:B,0) -> 64 | M4: =K4/J4 -> 0.0516 | N4: =K4/(J4/Z4*W$4) -> 0.31992 | O4: =VLOOKUP(B:B,X:Z,3,0) -> 7 | P4: =VLOOKUP(B:B,激励!A:B,2,0) -> 23.5 | Q4: 15 | R4: =_xlfn.XLOOKUP(B4,全光组网!A:A,全光组网!B:B,0) -> 2 | S4: =R4/Q4 -> 0.13333333 | V4: =MONTH(TODAY()-1)&"月" -> 8月 | W4: =DAY(TODAY()-1) -> 5 | Z4: =DAY(EOMONTH(TODAY(),0)) -> 31
B5: 黄淡妮 | C5: 14 | D5: =_xlfn.XLOOKUP(B5,高套!A:A,高套!B:B,0) -> 0 | E5: =D5/C5 -> 0 | F5: =D5/(C5/Z4*W$4) -> 0 | G5: =_xlfn.XLOOKUP(B5,红黄牌高套!A:A,红黄牌高套!B:B,0) -> 0 | H5: =IF(G5>=3,"否","是") -> 是 | I5: =IF(G5>=15,"金牌",IF(G5>=12,"银牌","")) | J5: 2500 | K5: =VLOOKUP(B:B,完美一单!A:C,3,0) -> 1145 | L5: =_xlfn.XLOOKUP(B5,净增积分!A:A,净增积分!B:B,0) -> 0 | M5: =K5/J5 -> 0.458 | N5: =K5/(J5/Z4*W$4) -> 2.8396 | O5: =VLOOKUP(B:B,X:Z,3,0) -> 1 | P5: =VLOOKUP(B:B,激励!A:B,2,0) -> 1587 | Q5: 15 | R5: =_xlfn.XLOOKUP(B5,全光组网!A:A,全光组网!B:B,0) -> 0 | S5: =R5/Q5 -> 0
B6: 邱海燕 | C6: 14 | D6: =_xlfn.XLOOKUP(B6,高套!A:A,高套!B:B,0) -> 0 | E6: =D6/C6 -> 0 | F6: =D6/(C6/Z4*W$4) -> 0 | G6: =_xlfn.XLOOKUP(B6,红黄牌高套!A:A,红黄牌高套!B:B,0) -> 0 | H6: =IF(G6>=3,"否","是") -> 是 | I6: =IF(G6>=15,"金牌",IF(G6>=12,"银牌","")) | J6: 2500 | K6: =VLOOKUP(B:B,完美一单!A:C,3,0) -> 29 | L6: =_xlfn.XLOOKUP(B6,净增积分!A:A,净增积分!B:B,0) -> 0 | M6: =K6/J6 -> 0.0116 | N6: =K6/(J6/Z4*W$4) -> 0.07192 | O6: =VLOOKUP(B:B,X:Z,3,0) -> 9 | P6: =VLOOKUP(B:B,激励!A:B,2,0) -> 43.5 | Q6: 15 | R6: =_xlfn.XLOOKUP(B6,全光组网!A:A,全光组网!B:B,0) -> 0 | S6: =R6/Q6 -> 0
B7: 李东 | C7: 14 | D7: =_xlfn.XLOOKUP(B7,高套!A:A,高套!B:B,0) -> 0 | E7: =D7/C7 -> 0 | F7: =D7/(C7/Z4*W$4) -> 0 | G7: =_xlfn.XLOOKUP(B7,红黄牌高套!A:A,红黄牌高套!B:B,0) -> 0 | H7: =IF(G7>=3,"否","是") -> 是 | I7: =IF(G7>=15,"金牌",IF(G7>=12,"银牌","")) | J7: 2500 | K7: =VLOOKUP(B:B,完美一单!A:C,3,0) -> 0 | L7: =_xlfn.XLOOKUP(B7,净增积分!A:A,净增积分!B:B,0) -> 0 | M7: =K7/J7 -> 0 | N7: =K7/(J7/Z4*W$4) -> 0 | O7: =VLOOKUP(B:B,X:Z,3,0) -> 10 | P7: =VLOOKUP(B:B,激励!A:B,2,0) -> 0 | Q7: 15 | R7: =_xlfn.XLOOKUP(B7,全光组网!A:A,全光组网!B:B,0) -> 0 | S7: =R7/Q7 -> 0
B8: 王锦添 | C8: 14 | D8: =_xlfn.XLOOKUP(B8,高套!A:A,高套!B:B,0) -> 0 | E8: =D8/C8 -> 0 | F8: =D8/(C8/Z4*W$4) -> 0 | G8: =_xlfn.XLOOKUP(B8,红黄牌高套!A:A,红黄牌高套!B:B,0) -> 0 | H8: =IF(G8>=3,"否","是") -> 是 | I8: =IF(G8>=15,"金牌",IF(G8>=12,"银牌","")) | J8: 2500 | K8: =VLOOKUP(B:B,完美一单!A:C,3,0) -> 41 | L8: =_xlfn.XLOOKUP(B8,净增积分!A:A,净增积分!B:B,0) -> -1941.01 | M8: =K8/J8 -> 0.0164 | N8: =K8/(J8/Z4*W$4) -> 0.10168 | O8: =VLOOKUP(B:B,X:Z,3,0) -> 8 | P8: =VLOOKUP(B:B,激励!A:B,2,0) -> 61.5 | Q8: 15 | R8: =_xlfn.XLOOKUP(B8,全光组网!A:A,全光组网!B:B,0) -> 0 | S8: =R8/Q8 -> 0 | X8: 邱海燕 | Y8: =VLOOKUP(X:X,B:K,10,0) -> 29 | Z8: =RANK(Y8,Y$8:Y$19,0) -> 9
B9: 黄观霞 | C9: 14 | D9: =_xlfn.XLOOKUP(B9,高套!A:A,高套!B:B,0) -> 0 | E9: =D9/C9 -> 0 | F9: =D9/(C9/Z4*W$4) -> 0 | G9: =_xlfn.XLOOKUP(B9,红黄牌高套!A:A,红黄牌高套!B:B,0) -> 0 | H9: =IF(G9>=3,"否","是") -> 是 | I9: =IF(G9>=15,"金牌",IF(G9>=12,"银牌","")) | J9: 2500 | K9: =VLOOKUP(B:B,完美一单!A:C,3,0) -> 228 | L9: =_xlfn.XLOOKUP(B9,净增积分!A:A,净增积分!B:B,0) -> 0 | M9: =K9/J9 -> 0.0912 | N9: =K9/(J9/Z4*W$4) -> 0.56544 | O9: =VLOOKUP(B:B,X:Z,3,0) -> 4 | P9: =VLOOKUP(B:B,激励!A:B,2,0) -> 88.5 | Q9: 15 | R9: =_xlfn.XLOOKUP(B9,全光组网!A:A,全光组网!B:B,0) -> 0 | S9: =R9/Q9 -> 0 | X9: 麦海芬 | Y9: =VLOOKUP(X:X,B:K,10,0) -> 129 | Z9: =RANK(Y9,Y$8:Y$19,0) -> 7
B10: 团队合计 | C10: =SUM(C4:C9) -> 84 | D10: =SUM(D4:D9) -> 1.5 | E10: =D10/C10 -> 0.017857143 | F10: =D10/(C10/Z4*W$4) -> 0.11071429 | G10: =SUM(G4:G9) -> 1.5 | J10: =SUM(J4:J9) -> 15000 | K10: =SUM(K4:K9) -> 1572 | L10: =SUM(L4:L9) -> -1877.01 | M10: =K10/J10 -> 0.1048 | N10: =K10/(J10/Z4*W$4) -> 0.64976 | Q10: =SUM(Q4:Q9) -> 90 | R10: =SUM(R4:R9) -> 2 | S10: =R10/Q10 -> 0.022222222 | X10: 黄淡妮 | Y10: =VLOOKUP(X:X,B:K,10,0) -> 1145 | Z10: =RANK(Y10,Y$8:Y$19,0) -> 1
A11: 大企业 团队 | B11: 谢卓和 | C11: 14 | D11: =_xlfn.XLOOKUP(B11,高套!A:A,高套!B:B,0) -> 0 | E11: =D11/C11 -> 0 | F11: =D11/(C11/Z4*W$4) -> 0 | G11: =_xlfn.XLOOKUP(B11,红黄牌高套!A:A,红黄牌高套!B:B,0) -> 0 | H11: =IF(G11>=3,"否","是") -> 是 | I11: =IF(G11>=15,"金牌",IF(G11>=12,"银牌","")) | J11: 2500 | K11: =VLOOKUP(B:B,完美一单!A:C,3,0) -> 468.17 | L11: =_xlfn.XLOOKUP(B11,净增积分!A:A,净增积分!B:B,0) -> 155.17 | M11: =K11/J11 -> 0.187268 | N11: =K11/(J11/Z4*W$4) -> 1.1610616 | O11: =VLOOKUP(B:B,X:Z,3,0) -> 3 | P11: =VLOOKUP(B:B,激励!A:B,2,0) -> 637.34 | Q11: 15 | R11: =_xlfn.XLOOKUP(B11,全光组网!A:A,全光组网!B:B,0) -> 0 | S11: =R11/Q11 -> 0 | X11: 李东 | Y11: =VLOOKUP(X:X,B:K,10,0) -> 0 | Z11: =RANK(Y11,Y$8:Y$19,0) -> 10
B12: 伍颖敏 | C12: 14 | D12: =_xlfn.XLOOKUP(B12,高套!A:A,高套!B:B,0) -> 4.5 | E12: =D12/C12 -> 0.32142857 | F12: =D12/(C12/Z4*W$4) -> 1.9928571 | G12: =_xlfn.XLOOKUP(B12,红黄牌高套!A:A,红黄牌高套!B:B,0) -> 6.5 | H12: =IF(G12>=3,"否","是") -> 否 | I12: =IF(G12>=15,"金牌",IF(G12>=12,"银牌","")) | J12: 2500 | K12: =VLOOKUP(B:B,完美一单!A:C,3,0) -> 580 | L12: =_xlfn.XLOOKUP(B12,净增积分!A:A,净增积分!B:B,0) -> 269 | M12: =K12/J12 -> 0.232 | N12: =K12/(J12/Z4*W$4) -> 1.4384 | O12: =VLOOKUP(B:B,X:Z,3,0) -> 2 | P12: =VLOOKUP(B:B,激励!A:B,2,0) -> 732 | Q12: 15 | R12: =_xlfn.XLOOKUP(B12,全光组网!A:A,全光组网!B:B,0) -> 0 | S12: =R12/Q12 -> 0 | X12: 王锦添 | Y12: =VLOOKUP(X:X,B:K,10,0) -> 41 | Z12: =RANK(Y12,Y$8:Y$19,0) -> 8
B13: 邓天群 | C13: 14 | D13: =_xlfn.XLOOKUP(B13,高套!A:A,高套!B:B,0) -> 0 | E13: =D13/C13 -> 0 | F13: =D13/(C13/Z4*W$4) -> 0 | G13: =_xlfn.XLOOKUP(B13,红黄牌高套!A:A,红黄牌高套!B:B,0) -> 0 | H13: =IF(G13>=3,"否","是") -> 是 | I13: =IF(G13>=15,"金牌",IF(G13>=12,"银牌","")) | J13: 2500 | K13: =VLOOKUP(B:B,完美一单!A:C,3,0) -> 0 | L13: =_xlfn.XLOOKUP(B13,净增积分!A:A,净增积分!B:B,0) -> 0 | M13: =K13/J13 -> 0 | N13: =K13/(J13/Z4*W$4) -> 0 | O13: =VLOOKUP(B:B,X:Z,3,0) -> 10 | P13: =VLOOKUP(B:B,激励!A:B,2,0) -> 0 | Q13: 15 | R13: =_xlfn.XLOOKUP(B13,全光组网!A:A,全光组网!B:B,0) -> 0 | S13: =R13/Q13 -> 0 | X13: 黄观霞 | Y13: =VLOOKUP(X:X,B:K,10,0) -> 228 | Z13: =RANK(Y13,Y$8:Y$19,0) -> 4
B14: 李玉强 | C14: 14 | D14: =_xlfn.XLOOKUP(B14,高套!A:A,高套!B:B,0) -> 4 | E14: =D14/C14 -> 0.28571429 | F14: =D14/(C14/Z4*W$4) -> 1.7714286 | G14: =_xlfn.XLOOKUP(B14,红黄牌高套!A:A,红黄牌高套!B:B,0) -> 10.35 | H14: =IF(G14>=3,"否","是") -> 否 | I14: =IF(G14>=15,"金牌",IF(G14>=12,"银牌","")) | J14: 2500 | K14: =VLOOKUP(B:B,完美一单!A:C,3,0) -> 163 | L14: =_xlfn.XLOOKUP(B14,净增积分!A:A,净增积分!B:B,0) -> 636.48 | M14: =K14/J14 -> 0.0652 | N14: =K14/(J14/Z4*W$4) -> 0.40424 | O14: =VLOOKUP(B:B,X:Z,3,0) -> 5 | P14: =VLOOKUP(B:B,激励!A:B,2,0) -> 253.5 | Q14: 15 | R14: =_xlfn.XLOOKUP(B14,全光组网!A:A,全光组网!B:B,0) -> 0 | S14: =R14/Q14 -> 0 | X14: 谢卓和 | Y14: =VLOOKUP(X:X,B:K,10,0) -> 468.17 | Z14: =RANK(Y14,Y$8:Y$19,0) -> 3
B15: 张小敏 | C15: 14 | D15: =_xlfn.XLOOKUP(B15,高套!A:A,高套!B:B,0) -> 0 | E15: =D15/C15 -> 0 | F15: =D15/(C15/Z4*W$4) -> 0 | G15: =_xlfn.XLOOKUP(B15,红黄牌高套!A:A,红黄牌高套!B:B,0) -> 2.57 | H15: =IF(G15>=3,"否","是") -> 是 | I15: =IF(G15>=15,"金牌",IF(G15>=12,"银牌","")) | J15: 2500 | K15: =VLOOKUP(B:B,完美一单!A:C,3,0) -> 154 | L15: =_xlfn.XLOOKUP(B15,净增积分!A:A,净增积分!B:B,0) -> 58 | M15: =K15/J15 -> 0.0616 | N15: =K15/(J15/Z4*W$4) -> 0.38192 | O15: =VLOOKUP(B:B,X:Z,3,0) -> 6 | P15: =VLOOKUP(B:B,激励!A:B,2,0) -> 539 | Q15: 15 | R15: =_xlfn.XLOOKUP(B15,全光组网!A:A,全光组网!B:B,0) -> 0 | S15: =R15/Q15 -> 0 | X15: 伍颖敏 | Y15: =VLOOKUP(X:X,B:K,10,0) -> 580 | Z15: =RANK(Y15,Y$8:Y$19,0) -> 2
B16: 具进康 | C16: 14 | D16: =_xlfn.XLOOKUP(B16,高套!A:A,高套!B:B,0) -> 0 | E16: =D16/C16 -> 0 | F16: =D16/(C16/Z4*W$4) -> 0 | G16: =_xlfn.XLOOKUP(B16,红黄牌高套!A:A,红黄牌高套!B:B,0) -> 0 | H16: =IF(G16>=3,"否","是") -> 是 | I16: =IF(G16>=15,"金牌",IF(G16>=12,"银牌","")) | J16: 2500 | K16: =VLOOKUP(B:B,完美一单!A:C,3,0) -> -1 | L16: =_xlfn.XLOOKUP(B16,净增积分!A:A,净增积分!B:B,0) -> 794 | M16: =K16/J16 -> -0.0004 | N16: =K16/(J16/Z4*W$4) -> -0.00248 | O16: =VLOOKUP(B:B,X:Z,3,0) -> 12 | P16: =VLOOKUP(B:B,激励!A:B,2,0) -> 98.5 | Q16: 15 | R16: =_xlfn.XLOOKUP(B16,全光组网!A:A,全光组网!B:B,0) -> 0 | S16: =R16/Q16 -> 0 | X16: 邓天群 | Y16: =VLOOKUP(X:X,B:K,10,0) -> 0 | Z16: =RANK(Y16,Y$8:Y$19,0) -> 10
B17: 团队合计 | C17: =SUM(C11:C16) -> 84 | D17: =SUM(D11:D16) -> 8.5 | E17: =D17/C17 -> 0.10119048 | F17: =D17/(C17/Z4*W$4) -> 0.62738095 | G17: =SUM(G11:G16) -> 19.42 | J17: =SUM(J11:J16) -> 15000 | K17: =SUM(K11:K16) -> 1364.17 | L17: =SUM(L11:L16) -> 1912.65 | M17: =K17/J17 -> 0.090944667 | N17: =K17/(J17/Z4*W$4) -> 0.56385693 | Q17: =SUM(Q11:Q16) -> 90 | R17: =SUM(R11:R16) -> 0 | S17: =R17/Q17 -> 0 | X17: 李玉强 | Y17: =VLOOKUP(X:X,B:K,10,0) -> 163 | Z17: =RANK(Y17,Y$8:Y$19,0) -> 5
A18: 合计 | C18: 165 | D18: =_xlfn.XLOOKUP("端州",高套!A:A,高套!B:B,0) -> 10 | E18: =D18/C18 -> 0.060606061 | F18: =D18/(C18/Z4*W$4) -> 0.37575758 | G18: =G10+G17 -> 20.92 | J18: =J10+J17 -> 30000 | K18: =K10+K17 -> 2936.17 | L18: =L10+L17 -> 35.64 | M18: =K18/J18 -> 0.097872333 | N18: =K18/(J18/Z4*W$4) -> 0.60680847 | P18: 政企 | Q18: 210 | R18: =R10+R17 -> 2 | S18: =R18/Q18 -> 0.0095238095 | X18: 具进康 | Y18: =VLOOKUP(X:X,B:K,10,0) -> -1 | Z18: =RANK(Y18,Y$8:Y$19,0) -> 12
P19: 端州 | Q19: 310 | R19: =_xlfn.XLOOKUP(P19,全光组网!A:A,全光组网!B:B,0) -> 31 | S19: =R19/Q19 -> 0.1 | X19: 张小敏 | Y19: =VLOOKUP(X:X,B:K,10,0) -> 154 | Z19: =RANK(Y19,Y$8:Y$19,0) -> 6
A20: 高端装维 | B20: 陈梓铭 | C20: - | D20: - | E20: - | F20: - | G20: =高装高套!B2 -> 0 | H20: - | J20: - | K20: =VLOOKUP(B:B,完美一单!A:C,3,0) -> 0 | M20: - | N20: - | O20: - | P20: =VLOOKUP(B:B,激励!A:B,2,0) -> 0 | Q20: - | R20: - | S20: -
B21: 程庆德 | C21: - | D21: - | E21: - | F21: - | G21: =高装高套!B3 -> 0 | H21: - | J21: - | K21: =VLOOKUP(B:B,完美一单!A:C,3,0) -> 0 | M21: - | N21: - | O21: - | P21: =VLOOKUP(B:B,激励!A:B,2,0) -> 0 | Q21: - | R21: - | S21: -
B22: 刘奇峻 | C22: - | D22: - | E22: - | F22: - | G22: =高装高套!B4 -> 0 | H22: - | J22: - | K22: =VLOOKUP(B:B,完美一单!A:C,3,0) -> 0 | M22: - | N22: - | O22: - | P22: =VLOOKUP(B:B,激励!A:B,2,0) -> 0 | Q22: - | R22: - | S22: -
B23: 龙家宝 | C23: - | D23: - | E23: - | F23: - | G23: =高装高套!B5 -> 0 | H23: - | J23: - | K23: =VLOOKUP(B:B,完美一单!A:C,3,0) -> 0 | M23: - | N23: - | O23: - | P23: =VLOOKUP(B:B,激励!A:B,2,0) -> 0 | Q23: - | R23: - | S23: -
B24: 罗紫杰 | C24: - | D24: - | E24: - | F24: - | G24: =高装高套!B6 -> 0 | H24: - | J24: - | K24: =VLOOKUP(B:B,完美一单!A:C,3,0) -> 0 | M24: - | N24: - | O24: - | P24: =VLOOKUP(B:B,激励!A:B,2,0) -> 0 | Q24: - | R24: - | S24: -
B25: 莫健铭 | C25: - | D25: - | E25: - | F25: - | G25: =高装高套!B7 -> 0 | H25: - | J25: - | K25: =VLOOKUP(B:B,完美一单!A:C,3,0) -> 0 | M25: - | N25: - | O25: - | P25: =VLOOKUP(B:B,激励!A:B,2,0) -> 0 | Q25: - | R25: - | S25: -
B26: 吴广仁 | C26: - | D26: - | E26: - | F26: - | G26: =高装高套!B8 -> 0 | H26: - | J26: - | K26: =VLOOKUP(B:B,完美一单!A:C,3,0) -> 0 | M26: - | N26: - | O26: - | P26: =VLOOKUP(B:B,激励!A:B,2,0) -> 0 | Q26: - | R26: - | S26: -
B27: 王洪明 | C27: - | D27: - | E27: - | F27: - | G27: =高装高套!B9 -> 0 | H27: - | J27: - | K27: =VLOOKUP(B:B,完美一单!A:C,3,0) -> 0 | M27: - | N27: - | O27: - | P27: =VLOOKUP(B:B,激励!A:B,2,0) -> 0 | Q27: - | R27: - | S27: -
A28: 高装合计 | C28: - | D28: - | E28: - | F28: - | G28: =SUM(G20:G27) -> 0 | H28: - | J28: - | K28: =SUM(K20:K27) -> 0 | M28: - | N28: - | O28: - | P28: - | Q28: - | R28: - | S28: -
A31: ="高装高套目标完成情况" -> 高装高套目标完成情况 | H31: ="全光任务完成情况" -> 全光任务完成情况 | N31: ="区县目标完成情况" -> 区县目标完成情况
A32: 岗位角色 | B32: 姓名 | C32: 高套目标 | D32: 高套发展 | E32: 积分完成 | F32: 积分激励预测(元) | H32: 岗位角色 | I32: 姓名 | J32: 发展目标 | K32: 协同CP发展的主从网关数 | L32: 完成率 | N32: 区县 | O32: 目标 | P32: 完成 | Q32: 净增积分 | R32: 完成率 | S32: 排名
A33: 高端装维 | B33: =高装高套!A2 -> 陈梓铭 | C33: 3.5 | D33: =高装高套!B2 -> 0 | E33: =VLOOKUP(B:B,完美一单!A:C,3,0) -> 0 | F33: =VLOOKUP(B:B,激励!A:B,2,0) -> 0 | H33: 智云工程师 | I33: 零樑 | J33: 60 | K33: =交付高装!D2 -> 0 | L33: =交付高装!E2 -> 0 | N33: 端州 | O33: 5.3 | P33: =ROUND(_xlfn.XLOOKUP(N33,高套!A:A,高套!B:B,0)/W4,2) -> 2 | Q33: =_xlfn.XLOOKUP(N33,净增积分!A:A,净增积分!B:B,0) -> 1122.06 | R33: =P33/O33 -> 0.37735849 | S33: =RANK(R33,R33:R41) -> 3
B34: =高装高套!A3 -> 程庆德 | C34: 3.5 | D34: =高装高套!B3 -> 0 | E34: =VLOOKUP(B:B,完美一单!A:C,3,0) -> 0 | F34: =VLOOKUP(B:B,激励!A:B,2,0) -> 0 | I34: 何而恒 | J34: 60 | K34: =交付高装!D3 -> 0 | L34: =交付高装!E3 -> 0 | N34: 高要 | O34: 5.7 | P34: =ROUND(_xlfn.XLOOKUP(N34,高套!A:A,高套!B:B,0)/W4,2) -> 5.8 | Q34: =_xlfn.XLOOKUP(N34,净增积分!A:A,净增积分!B:B,0) -> -5728.86 | R34: =P34/O34 -> 1.0175439 | S34: =RANK(R34,R33:R41) -> 1
B35: =高装高套!A4 -> 刘奇峻 | C35: 3.5 | D35: =高装高套!B4 -> 0 | E35: =VLOOKUP(B:B,完美一单!A:C,3,0) -> 0 | F35: =VLOOKUP(B:B,激励!A:B,2,0) -> 0 | I35: 魏垚晖 | J35: 60 | K35: =交付高装!D4 -> 2 | L35: =交付高装!E4 -> 0.033333333 | N35: 四会 | O35: 5 | P35: =ROUND(_xlfn.XLOOKUP(N35,高套!A:A,高套!B:B,0)/W4,2) -> 1.33 | Q35: =_xlfn.XLOOKUP(N35,净增积分!A:A,净增积分!B:B,0) -> -594.98 | R35: =P35/O35 -> 0.266 | S35: =RANK(R35,R33:R41) -> 5
B36: =高装高套!A5 -> 龙家宝 | C36: 3.5 | D36: =高装高套!B5 -> 0 | E36: =VLOOKUP(B:B,完美一单!A:C,3,0) -> 0 | F36: =VLOOKUP(B:B,激励!A:B,2,0) -> 0 | I36: 吴文懿 | J36: 45 | K36: =交付高装!D5 -> 0 | L36: =交付高装!E5 -> 0 | N36: 怀集 | O36: 5 | P36: =ROUND(_xlfn.XLOOKUP(N36,高套!A:A,高套!B:B,0)/W4,2) -> 1.4 | Q36: =_xlfn.XLOOKUP(N36,净增积分!A:A,净增积分!B:B,0) -> 2163.12 | R36: =P36/O36 -> 0.28 | S36: =RANK(R36,R33:R41) -> 4
B37: =高装高套!A6 -> 罗紫杰 | C37: 3.5 | D37: =高装高套!B6 -> 0 | E37: =VLOOKUP(B:B,完美一单!A:C,3,0) -> 0 | F37: =VLOOKUP(B:B,激励!A:B,2,0) -> 0 | H37: 高端装维 | I37: 陈梓铭 | J37: 30 | K37: =交付高装!D6 -> 0 | L37: =交付高装!E6 -> 0 | N37: 德庆 | O37: 3.4 | P37: =ROUND(_xlfn.XLOOKUP(N37,高套!A:A,高套!B:B,0)/W4,2) -> 0.2 | Q37: =_xlfn.XLOOKUP(N37,净增积分!A:A,净增积分!B:B,0) -> -18358.2 | R37: =P37/O37 -> 0.058823529 | S37: =RANK(R37,R33:R41) -> 7
B38: =高装高套!A7 -> 莫健铭 | C38: 3.5 | D38: =高装高套!B7 -> 0 | E38: =VLOOKUP(B:B,完美一单!A:C,3,0) -> 0 | F38: =VLOOKUP(B:B,激励!A:B,2,0) -> 0 | I38: 程庆德 | J38: 30 | K38: =交付高装!D7 -> 0 | L38: =交付高装!E7 -> 0 | N38: 广宁 | O38: 3.6 | P38: =ROUND(_xlfn.XLOOKUP(N38,高套!A:A,高套!B:B,0)/W4,2) -> 0.2 | Q38: =_xlfn.XLOOKUP(N38,净增积分!A:A,净增积分!B:B,0) -> 1098.45 | R38: =P38/O38 -> 0.055555556 | S38: =RANK(R38,R33:R41) -> 8
B39: =高装高套!A8 -> 吴广仁 | C39: 3.5 | D39: =高装高套!B8 -> 0 | E39: =VLOOKUP(B:B,完美一单!A:C,3,0) -> 0 | F39: =VLOOKUP(B:B,激励!A:B,2,0) -> 0 | I39: 刘奇峻 | J39: 30 | K39: =交付高装!D8 -> 0 | L39: =交付高装!E8 -> 0 | N39: 封开 | O39: 3.4 | P39: =ROUND(_xlfn.XLOOKUP(N39,高套!A:A,高套!B:B,0)/W4,2) -> 0 | Q39: =_xlfn.XLOOKUP(N39,净增积分!A:A,净增积分!B:B,0) -> 1085.2 | R39: =P39/O39 -> 0 | S39: =RANK(R39,R33:R41) -> 9
B40: =高装高套!A9 -> 王洪明 | C40: 3.5 | D40: =高装高套!B9 -> 0 | E40: =VLOOKUP(B:B,完美一单!A:C,3,0) -> 0 | F40: =VLOOKUP(B:B,激励!A:B,2,0) -> 0 | I40: 龙家宝 | J40: 30 | K40: =交付高装!D9 -> 0 | L40: =交付高装!E9 -> 0 | N40: 鼎湖 | O40: 4.2 | P40: =ROUND(_xlfn.XLOOKUP(N40,高套!A:A,高套!B:B,0)/W4,2) -> 2.75 | Q40: =_xlfn.XLOOKUP(N40,净增积分!A:A,净增积分!B:B,0) -> -110.22 | R40: =P40/O40 -> 0.6547619 | S40: =RANK(R40,R33:R41) -> 2
A41: 合计 | C41: =SUM(C33:C40) -> 28 | D41: =SUM(D33:D40) -> 0 | E41: =SUM(E33:E40) -> 0 | F41: - | I41: 罗紫杰 | J41: 30 | K41: =交付高装!D10 -> 0 | L41: =交付高装!E10 -> 0 | N41: 高新 | O41: 4.4 | P41: =ROUND(_xlfn.XLOOKUP(N41,高套!A:A,高套!B:B,0)/W4,2) -> 1.09 | Q41: =_xlfn.XLOOKUP(N41,净增积分!A:A,净增积分!B:B,0) -> 1289.13 | R41: =P41/O41 -> 0.24772727 | S41: =RANK(R41,R33:R41) -> 6
I42: 莫健铭 | J42: 30 | K42: =交付高装!D11 -> 2 | L42: =交付高装!E11 -> 0.066666667 | N42: 合 计 | O42: =SUM(O33:O41) -> 40 | P42: =SUM(P33:P41) -> 14.77 | Q42: =SUM(Q33:Q41) -> -18034.3 | R42: =P42/O42 -> 0.36925
...

Sheet 高套
A1: 姓名 | B1: 高套数
A2: 钟俊杰 | B2: 0
A3: 麦海芬 | B3: 1.5
A4: 黄淡妮 | B4: 0
A5: 邱海燕 | B5: 0
A6: 李东 | B6: 0
A7: 王锦添 | B7: 0
A8: 黄观霞 | B8: 0
A9: 谢卓和 | B9: 0
A10: 伍颖敏 | B10: 4.5
A11: 潘观友 | B11: 0
A12: 李玉强 | B12: 4
A13: 张小敏 | B13: 0
... A25: 封开 | B25: 0

Sheet 全光组网
A1: 姓名 | B1: 主从网关数
A2: 钟俊杰 | B2: 0
A3: 麦海芬 | B3: 2
A4: 黄淡妮 | B4: 0
A5: 邱海燕 | B5: 0
A6: 李东 | B6: 0
A7: 王锦添 | B7: 0
A8: 黄观霞 | B8: 0
A9: 谢卓和 | B9: 0
A10: 伍颖敏 | B10: 0
A11: 潘观友 | B11: 0
A12: 李玉强 | B12: 0
A13: 张小敏 | B13: 0
... A17: 端州 | B17: 31

Sheet 完美一单
A1: 姓名 | B1: 高套 | C1: 积分完成 | D1: 新增积分（全业务）
A2: 钟俊杰 | B2: 0 | C2: 0 | D2: 0
A3: 麦海芬 | B3: 1.5 | C3: 129 | D3: 29
A4: 黄淡妮 | B4: 0 | C4: 1145 | D4: 1164
A5: 邱海燕 | B5: 0 | C5: 29 | D5: 29
A6: 李东 | B6: 0 | C6: 0 | D6: 0
A7: 王锦添 | B7: 0 | C7: 41 | D7: 41
A8: 黄观霞 | B8: 0 | C8: 228 | D8: 59
A9: 谢卓和 | B9: 0 | C9: 468.17 | D9: 598
A10: 伍颖敏 | B10: 6.5 | C10: 580 | D10: 240
A11: 潘观友 | B11: 3 | C11: 615 | D11: 585
A12: 李玉强 | B12: 10.35 | C12: 163 | D12: 0
A13: 张小敏 | B13: 2.57 | C13: 154 | D13: 0
... A24: 王洪明 | B24: 0 | C24: 0 | D24: 0

Sheet 高装高套
A1: 姓名 | B1: 高套数 | C1: 高套目标
A2: 陈梓铭 | B2: 0 | C2: 1
A3: 程庆德 | B3: 0 | C3: 1
A4: 刘奇峻 | B4: 0 | C4: 1
A5: 龙家宝 | B5: 0 | C5: 1
A6: 罗紫杰 | B6: 0 | C6: 1
A7: 莫健铭 | B7: 0 | C7: 1
A8: 吴广仁 | B8: 0 | C8: 1
A9: 王洪明 | B9: 0 | C9: 1

Sheet 红黄牌高套
A1: 姓名 | B1: 高套数
A2: 钟俊杰 | B2: 0
A3: 麦海芬 | B3: 1.5
A4: 黄淡妮 | B4: 0
A5: 邱海燕 | B5: 0
A6: 李东 | B6: 0
A7: 王锦添 | B7: 0
A8: 黄观霞 | B8: 0
A9: 谢卓和 | B9: 0
A10: 伍颖敏 | B10: 6.5
A11: 潘观友 | B11: 3
A12: 李玉强 | B12: 10.35
A13: 张小敏 | B13: 2.57
... A16: 张端 | B16: 0

Sheet 交付高装
A1: 岗位角色 | B1: 姓名 | C1: 发展目标 | D1: 主从网关数 | E1: 完成率 | J1: 负责客户经理 | K1: 装维协同结对 | L1: 装维负责区域 | M1: 协同交付经理
A2: 智云工程师 | B2: 零樑 | C2: 60 | D2: {=SUMPRODUCT(SUMIF(全光组网!A:A,$J$2:$J$16,全光组网!B:B)*($M$2:$M$16=B2))} -> 0 | E2: =D2/C2 -> 0 | J2: 邓天群 | K2: 陈梓铭 | L2: 城东 | M2: 何而恒
A3: 智云工程师 | B3: 何而恒 | C3: 60 | D3: {=SUMPRODUCT(SUMIF(全光组网!A:A,$J$2:$J$16,全光组网!B:B)*($M$2:$M$16=B3))} -> 0 | E3: =D3/C3 -> 0 | J3: 黄观霞 | K3: 陈梓铭 | L3: 城东 | M3: 何而恒
A4: 智云工程师 | B4: 魏垚晖 | C4: 60 | D4: {=SUMPRODUCT(SUMIF(全光组网!A:A,$J$2:$J$16,全光组网!B:B)*($M$2:$M$16=B4))} -> 2 | E4: =D4/C4 -> 0.033333333 | J4: 王锦添 | K4: 程庆德 | L4: 城中 | M4: 何而恒
A5: 智云工程师 | B5: 吴文懿 | C5: 45 | D5: {=SUMPRODUCT(SUMIF(全光组网!A:A,$J$2:$J$16,全光组网!B:B)*($M$2:$M$16=B5))} -> 0 | E5: =D5/C5 -> 0 | J5: 钟俊杰 | K5: 程庆德 | L5: 城中 | M5: 何而恒
A6: 高端装维 | B6: 陈梓铭 | C6: 30 | D6: {=SUMPRODUCT(SUMIF(全光组网!A:A,$J$2:$J$16,全光组网!B:B)*($K$2:$K$16=B6))} -> 0 | E6: =D6/C6 -> 0 | J6: 伍颖敏 | K6: 刘奇峻 | L6: 城中 | M6: 零樑
A7: 高端装维 | B7: 程庆德 | C7: 30 | D7: {=SUMPRODUCT(SUMIF(全光组网!A:A,$J$2:$J$16,全光组网!B:B)*($K$2:$K$16=B7))} -> 0 | E7: =D7/C7 -> 0 | J7: 邱海燕 | K7: 刘奇峻 | L7: 城中 | M7: 零樑
A8: 高端装维 | B8: 刘奇峻 | C8: 30 | D8: {=SUMPRODUCT(SUMIF(全光组网!A:A,$J$2:$J$16,全光组网!B:B)*($K$2:$K$16=B8))} -> 0 | E8: =D8/C8 -> 0 | J8: 黄淡妮 | K8: 龙家宝 | L8: 城西 | M8: 零樑
A9: 高端装维 | B9: 龙家宝 | C9: 30 | D9: {=SUMPRODUCT(SUMIF(全光组网!A:A,$J$2:$J$16,全光组网!B:B)*($K$2:$K$16=B9))} -> 0 | E9: =D9/C9 -> 0 | J9: 李东 | K9: 龙家宝 | L9: 城西 | M9: 零樑
A10: 高端装维 | B10: 罗紫杰 | C10: 30 | D10: {=SUMPRODUCT(SUMIF(全光组网!A:A,$J$2:$J$16,全光组网!B:B)*($K$2:$K$16=B10))} -> 0 | E10: =D10/C10 -> 0 | J10: 张端 | K10: 罗紫杰 | L10: 城西 | M10: 魏垚晖
A11: 高端装维 | B11: 莫健铭 | C11: 30 | D11: {=SUMPRODUCT(SUMIF(全光组网!A:A,$J$2:$J$16,全光组网!B:B)*($K$2:$K$16=B11))} -> 2 | E11: =D11/C11 -> 0.066666667 | J11: 谢卓和 | K11: 罗紫杰 | L11: 城西 | M11: 魏垚晖
A12: 高端装维 | B12: 吴广仁 | C12: 30 | D12: {=SUMPRODUCT(SUMIF(全光组网!A:A,$J$2:$J$16,全光组网!B:B)*($K$2:$K$16=B12))} -> 0 | E12: =D12/C12 -> 0 | J12: 李玉强 | K12: 莫健铭 | L12: 城东 | M12: 魏垚晖
A13: 高端装维 | B13: 王洪明 | C13: 25 | D13: {=SUMPRODUCT(SUMIF(全光组网!A:A,$J$2:$J$16,全光组网!B:B)*($K$2:$K$16=B13))} -> 0 | E13: =D13/C13 -> 0 | J13: 麦海芬 | K13: 莫健铭 | L13: 城东 | M13: 魏垚晖
J14: 具进康 | K14: 吴广仁 | L14: 城西 | M14: 吴文懿
J15: 张小敏 | K15: 吴广仁 | L15: 城西 | M15: 吴文懿
J16: 陈泳诗（休产假） | K16: 王洪明（技能待提升，4月需协同其他装维上门) | L16: 城东 | M16: 吴文懿

Sheet 激励
A1: 姓名 | B1: 激励金额
A2: 钟俊杰 | B2: 0
A3: 麦海芬 | B3: 23.5
A4: 黄淡妮 | B4: 1587
A5: 邱海燕 | B5: 43.5
A6: 李东 | B6: 0
A7: 王锦添 | B7: 61.5
A8: 黄观霞 | B8: 88.5
A9: 谢卓和 | B9: 637.34
A10: 伍颖敏 | B10: 732
A11: 潘观友 | B11: 1901
A12: 李玉强 | B12: 253.5
A13: 张小敏 | B13: 539
... A24: 王洪明 | B24: 0

Sheet 积分
A1: 净增积分 | B1: 基本面 | C1: 双线 | D1: 增量积分落格率
A2: 1294.22 | B2: -415.28 | C2: 1100 | D2: 0.39

Sheet 净增积分
A1: 姓名 | B1: 净增积分
A2: 麦海芬 | B2: 64
A3: 黄淡妮 | B3: 0
A4: 邱海燕 | B4: 0
A5: 李东 | B5: 0
A6: 王锦添 | B6: -1941.01
A7: 黄观霞 | B7: 0
A8: 谢卓和 | B8: 155.17
A9: 伍颖敏 | B9: 269
A10: 邓天群 | B10: 0
A11: 李玉强 | B11: 636.48
A12: 张小敏 | B12: 58
A13: 具进康 | B13: 794
... A22: 高新 | B22: 1289.13
